<?xml version="1.0"?>

<robot name="scanner" xmlns:xacro="http://www.w3.org/1999/XSL/Transform">
    <xacro:arg name="laser_enabled" default="true" />

    <!-- main link -->
    <link name="world"/>
    <joint name="fixed" type="fixed">
        <parent link="world"/>
        <child link="base_link"/>
    </joint>

    <!--base-->
    <link name="base_link">
        <collision>
            <origin rpy="0 0 0" xyz="0 0 0"/>
            <geometry>
                <box size="0.295 0.148 0.07"/>
            </geometry>
        </collision>
        <visual>
            <origin rpy="0 0 0" xyz="0 0 0"/>
            <geometry>
                <box size="0.295 0.148 0.07"/>
            </geometry>
            <material name="black">
                <color rgba="0.1 0.1 0.1 1"/>
            </material>
        </visual>
        <inertial>
            <origin rpy="0 0 0" xyz="0 0 0"/>
            <mass value="20"/>
            <inertia
                    ixx="0.1" ixy="0.1" ixz="0.1"
                    iyy="0.1" iyz="0.1"
                    izz="0.1"/>
        </inertial>
    </link>

    <!--lidar stand-->
    <link name="lidar_stand">
        <collision>
            <geometry>
                <box size="0.075 0.012 "/>
            </geometry>
            <material name="orange">
                <color rgba="1 0.45 0 1"/>
            </material>
            <origin rpy="0 0 0" xyz="0 0 0"/>
        </collision>
        <visual>
            <geometry>
                <box size="0.075 0.012 "/>
            </geometry>
            <material name="orange">
                <color rgba="1 0.45 0 1"/>
            </material>
            <origin rpy="0 0 0" xyz="0 0 0"/>
        </visual>
        <inertial>
            <origin rpy="0 0 0" xyz="0 0 0"/>
            <mass value="2"/>
            <inertia
                    ixx="0.1" ixy="0.1" ixz="0.1"
                    iyy="0.1" iyz="0.1"
                    izz="0.1"/>
        </inertial>
    </link>

    <joint name="base_to_arm1" type="revolute">
        <origin xyz="0 0 0.495" rpy="0 0 0"/>
        <axis xyz="0 0 1"/>
        <limit effort="1000" lower="-3.141" upper="3.141" velocity="3.054"/>
        <parent link="base_link"/>
        <child link="arm1"/>
        <dynamics damping="50"/>
    </joint>

    <transmission name="base_to_arm1_trans">
        <type>transmission_interface/SimpleTransmission</type>
        <joint name="base_to_arm1">
            <hardwareInterface>hardware_interface/EffortJointInterface</hardwareInterface>
        </joint>
        <actuator name="motor1_actuator">
            <mechanicalReduction>50</mechanicalReduction>
            <hardwareInterface>hardware_interface/EffortJointInterface</hardwareInterface>
        </actuator>
    </transmission>

    <!--arm2-->
    <link name="arm2">
        <collision>
            <geometry>
                <mesh filename="package://kr16_pkg/kr16_parts/meshes/irb4600_60_205/collision/link_2.stl"/>
            </geometry>
            <material name="orange"/>
            <origin rpy="0 0 0" xyz="0 0 0"/>
        </collision>
        <visual>
            <geometry>
                <mesh filename="package://kr16_pkg/kr16_parts/meshes/irb4600_60_205/visual/link_2.stl"/>
            </geometry>
            <material name="orange"/>
            <origin rpy="0 0 0" xyz="0 0 0"/>
        </visual>
        <inertial>
            <origin rpy="0 0 0" xyz="0 0 0"/>
            <mass value="1.2"/>
            <inertia
                    ixx="0.1" ixy="0.1" ixz="0.1"
                    iyy="0.1" iyz="0.1"
                    izz="0.1"/>
        </inertial>
    </link>

    <joint name="arm1_to_arm2" type="revolute">
        <origin xyz="0.175 0 0" rpy="0 0 0"/>
        <axis xyz="0 1 0"/>
        <limit effort="1000" lower="-1.570" upper="2.617" velocity="3.054"/>
        <parent link="arm1"/>
        <child link="arm2"/>
        <dynamics damping="50"/>
    </joint>

    <transmission name="arm1_to_arm2_trans">
        <type>transmission_interface/SimpleTransmission</type>
        <joint name="arm1_to_arm2">
            <hardwareInterface>hardware_interface/EffortJointInterface</hardwareInterface>
        </joint>
        <actuator name="motor2_actuator">
            <mechanicalReduction>50</mechanicalReduction>
            <hardwareInterface>hardware_interface/EffortJointInterface</hardwareInterface>
        </actuator>
    </transmission>

    <!--arm3-->
    <link name="arm3">
        <collision>
            <geometry>
                <mesh filename="package://kr16_pkg/kr16_parts/meshes/irb4600_60_205/collision/link_3.stl"/>
            </geometry>
            <material name="orange"/>
            <origin rpy="0 0 0" xyz="0 0 0"/>
        </collision>
        <visual>
            <geometry>
                <mesh filename="package://kr16_pkg/kr16_parts/meshes/irb4600_60_205/visual/link_3.stl"/>
            </geometry>
            <material name="orange"/>
            <origin rpy="0 0 0" xyz="0 0 0"/>
        </visual>
        <inertial>
            <origin rpy="0 0 0" xyz="0 0 0"/>
            <mass value="1"/>
            <inertia
                    ixx="0.1" ixy="0.1" ixz="0.1"
                    iyy="0.1" iyz="0.1"
                    izz="0.1"/>
        </inertial>
    </link>

    <joint name="arm2_to_arm3" type="revolute">
        <origin xyz="0 0 0.9" rpy="0 0 0"/>
        <axis xyz="0 1 0"/>
        <limit effort="1000" lower="-3.141" upper="1.308" velocity="3.054"/>
        <parent link="arm2"/>
        <child link="arm3"/>
        <dynamics damping="50"/>
    </joint>

    <transmission name="arm2_to_arm3_trans">
        <type>transmission_interface/SimpleTransmission</type>
        <joint name="arm2_to_arm3">
            <hardwareInterface>hardware_interface/EffortJointInterface</hardwareInterface>
        </joint>
        <actuator name="motor3_actuator">
            <mechanicalReduction>50</mechanicalReduction>
            <hardwareInterface>hardware_interface/EffortJointInterface</hardwareInterface>
        </actuator>
    </transmission>

    <!--arm4-->
    <link name="arm4">
        <collision>
            <geometry>
                <mesh filename="package://kr16_pkg/kr16_parts/meshes/irb4600_60_205/collision/link_4.stl"/>
            </geometry>
            <material name="orange"/>
            <origin rpy="0 0 0" xyz="0 0 0"/>
        </collision>
        <visual>
            <geometry>
                <mesh filename="package://kr16_pkg/kr16_parts/meshes/irb4600_60_205/visual/link_4.stl"/>
            </geometry>
            <material name="orange"/>
            <origin rpy="0 0 0" xyz="0 0 0"/>
        </visual>
        <inertial>
            <origin rpy="0 0 0" xyz="0 0 0"/>
            <mass value="0.7"/>
            <inertia
                    ixx="0.1" ixy="0.1" ixz="0.1"
                    iyy="0.1" iyz="0.1"
                    izz="0.1"/>
        </inertial>
    </link>

    <joint name="arm3_to_arm4" type="revolute">
        <origin xyz="0 0 0.175" rpy="0 0 0"/>
        <axis xyz="1 0 0"/>
        <limit effort="1000" lower="-6.981" upper="6.981" velocity="4.363"/>
        <parent link="arm3"/>
        <child link="arm4"/>
        <dynamics damping="50"/>
    </joint>

    <transmission name="arm3_to_arm4_trans">
        <type>transmission_interface/SimpleTransmission</type>
        <joint name="arm3_to_arm4">
            <hardwareInterface>hardware_interface/EffortJointInterface</hardwareInterface>
        </joint>
        <actuator name="motor4_actuator">
            <mechanicalReduction>50</mechanicalReduction>
            <hardwareInterface>hardware_interface/EffortJointInterface</hardwareInterface>
        </actuator>
    </transmission>

    <!--arm5-->
    <link name="arm5">
        <collision>
            <geometry>
                <mesh filename="package://kr16_pkg/kr16_parts/meshes/irb4600_60_205/collision/link_5.stl"/>
            </geometry>
            <material name="orange"/>
            <origin rpy="0 0 0" xyz="0 0 0"/>
        </collision>
        <visual>
            <geometry>
                <mesh filename="package://kr16_pkg/kr16_parts/meshes/irb4600_60_205/visual/link_5.stl"/>
            </geometry>
            <material name="orange"/>
            <origin rpy="0 0 0" xyz="0 0 0"/>
        </visual>
        <inertial>
            <origin rpy="0 0 0" xyz="0 0 0"/>
            <mass value="50"/>
            <inertia
                    ixx="0.1" ixy="0.1" ixz="0.1"
                    iyy="0.1" iyz="0.1"
                    izz="0.1"/>
        </inertial>
    </link>

    <joint name="arm4_to_arm5" type="revolute">
        <origin xyz="0.960 0 0 " rpy="0 0 0"/>
        <axis xyz="0 1 0"/>
        <limit effort="1000" lower="-2.181" upper="2.094" velocity="4.363"/>
        <parent link="arm4"/>
        <child link="arm5"/>
        <dynamics damping="50"/>
    </joint>

    <transmission name="arm4_to_arm5_trans">
        <type>transmission_interface/SimpleTransmission</type>
        <joint name="arm4_to_arm5">
            <hardwareInterface>hardware_interface/EffortJointInterface</hardwareInterface>
        </joint>
        <actuator name="motor5_actuator">
            <mechanicalReduction>50</mechanicalReduction>
            <hardwareInterface>hardware_interface/EffortJointInterface</hardwareInterface>
        </actuator>
    </transmission>

    <!--actuator-->
    <link name="actuator">
        <collision>
            <geometry>
                <mesh filename="package://kr16_pkg/kr16_parts/meshes/irb4600_60_205/collision/link_6.stl"/>
            </geometry>
            <material name="black"/>
            <origin rpy="0 -${pi/2} 0" xyz="0 0 0"/>
            <!--<origin rpy="0 0 -${pi/2}" xyz="0 0 0"/>-->
        </collision>
        <visual>
            <geometry>
                <mesh filename="package://kr16_pkg/kr16_parts/meshes/irb4600_60_205/visual/link_6.stl"/>
            </geometry>
            <material name="black"/>
            <origin rpy="0 -${pi/2} 0" xyz="0 0 0"/>
        </visual>
        <inertial>
            <origin rpy="0 -${pi/2} 0" xyz="0 0 0"/>
            <mass value="0.100"/>
            <inertia
                    ixx="0.1" ixy="0.1" ixz="0.1"
                    iyy="0.1" iyz="0.1"
                    izz="0.1"/>
        </inertial>
    </link>

    <joint name="arm5_to_actuator" type="revolute">
        <origin xyz="0.135 0 0 " rpy="0 ${pi/2} 0"/>
        <axis xyz="0 0 1"/>
        <limit effort="1000" lower="-6.981" upper="6.981" velocity="6.283"/>
         <parent link="arm5"/>
        <child link="actuator"/>
        <dynamics damping="50"/>
    </joint>

    <transmission name="arm5_to_actuator_trans">
        <type>transmission_interface/SimpleTransmission</type>
        <joint name="arm5_to_actuator">
            <hardwareInterface>hardware_interface/EffortJointInterface</hardwareInterface>
        </joint>
        <actuator name="motor6_actuator">
            <mechanicalReduction>50</mechanicalReduction>
            <hardwareInterface>hardware_interface/EffortJointInterface</hardwareInterface>
        </actuator>
    </transmission>

    <!-- laser -->
    <link name="laser_origin">
        <visual>
            <geometry>
                <box size="0.0001 0.0001 0.0001" />
            </geometry>
            <material name="purple">
                <color rgba="1 0 1 0"/>
            </material>
            <origin rpy="0 0 0" xyz="0 0 0"/>
        </visual>
        <inertial>
            <origin rpy="0 0 0" xyz="0 0 0"/>
            <mass value="0"/>
            <inertia
                    ixx="0.0" ixy="0.0" ixz="0.0"
                    iyy="0.0" iyz="0.0"
                    izz="0.0"/>
        </inertial>
    </link>

    <joint name="micro_epsilon_box_to_laser_origin" type="fixed">
        <parent link="actuator"/>
        <child link="laser_origin"/>
        <origin rpy="0 0 -${pi/4}" xyz="0.089 0.035 0.33"/> <!--<origin rpy="0 0 -${pi/2}" xyz="0.089 0.035 0.33"/> to center x = 0.0325-->
    </joint>

    <gazebo reference="laser_origin">
        <sensor name="micro_epsilon" type="ray">
            <!--<pose>0 0 1000 0 -${pi/2} -${pi/2}</pose>  <pose>0 -0.1 0 -${pi/2} 0 -${pi/2}</pose> -->
            <ray>
                <scan>
                    <horizontal>
                        <samples>1280</samples>
                        <resolution>1</resolution>
                        <min_angle>-0.298</min_angle><!--width 40mm to 60mm -->
                        <max_angle>0.298</max_angle>
                    </horizontal>
                </scan>
                <range>
                    <min>0.065</min>
                    <max>0.125</max>
                    <resolution>0.005</resolution>
                </range>
                <noise>
                    <type>gaussian</type>
                    <mean>0.00001</mean>
                    <stddev>0.00001</stddev>
                </noise>
            </ray>
            <plugin name="gazebo_ros_head_hokuyo_controller" filename="libgazebo_ros_laser.so">
                <topicName>/microepsilon_topic</topicName>
                <frameName>laser_origin</frameName><!--<frameName>arm5_to_actuator</frameName>-->
            </plugin>
            <always_on>1</always_on>
            <update_rate>100</update_rate>
            <visualize>true</visualize>
        </sensor>
    </gazebo>

    <xacro:if value="$(arg laser_enabled)">
        <!--laser_model-->
        <link name="laser_model">
            <collision>
                <geometry>
                    <box size="0.0001 0.0001 0.0001" />
                </geometry>
                <material name="black"/>
                <origin rpy="0 0 0" xyz="0 0 0"/>
            </collision>
            <visual>
                <geometry>
                    <mesh filename="package://kr16_pkg/kr16_parts/laser.stl" scale="0.001 0.001 0.001"/>
                </geometry>
                <material name="blue">
                    <color rgba="0 0 1 1"/>
                </material>
                <origin rpy="0 0 0" xyz="0 0 0"/>
            </visual>
            <inertial>
                <origin rpy="0 0 0" xyz="0 0 0"/>
                <mass value="0"/>
                <inertia
                        ixx="0.0" ixy="0.0" ixz="0.0"
                        iyy="0.0" iyz="0.0"
                        izz="0.0"/>
            </inertial>
        </link>

        <!--<joint name="laser_origin_to_laser_model" type="fixed">
            <parent link="laser_origin"/>
            <child link="laser_model"/>
            <origin rpy="-${pi/2} 0 -${pi/2}" xyz="0.065 0 0"/>
        </joint>-->
        <joint name="laser_origin_to_laser_model" type="fixed">
            <parent link="laser_origin"/>
            <child link="laser_model"/>
            <origin rpy="0 0 0" xyz="0 0 0"/>
        </joint>
    </xacro:if>


    <!-- ros control plugin -->
    <gazebo>
        <plugin name="gazebo_ros_control" filename="libgazebo_ros_control.so">
            <robotNamespace>/</robotNamespace>
        </plugin>
    </gazebo>

</robot>




